<?xml version="1.0" encoding="UTF-8"?>
<!-- Generated by org.testng.reporters.JUnitReportReporter -->
<testsuite hostname="Aravindh-PC" failures="0" tests="11" name="mytests.RetryAnalyzer" time="0.079" errors="2" timestamp="01 May 2019 02:35:10 GMT" skipped="8">
  <testcase classname="mytests.RetryAnalyzer" name="test1" time="0.003">
    <error message="expected:&lt;true&gt; but was:&lt;false&gt;" type="junit.framework.AssertionFailedError">
      <![CDATA[junit.framework.AssertionFailedError: expected:<true> but was:<false>
at junit.framework.Assert.fail(Assert.java:47)
at junit.framework.Assert.failNotEquals(Assert.java:282)
at junit.framework.Assert.assertEquals(Assert.java:64)
at junit.framework.Assert.assertEquals(Assert.java:149)
at junit.framework.Assert.assertEquals(Assert.java:155)
at mytests.RetryAnalyzer.test1(RetryAnalyzer.java:11)
at java.base/jdk.internal.reflect.NativeMethodAccessorImpl.invoke0(Native Method)
at java.base/jdk.internal.reflect.NativeMethodAccessorImpl.invoke(NativeMethodAccessorImpl.java:62)
at java.base/jdk.internal.reflect.DelegatingMethodAccessorImpl.invoke(DelegatingMethodAccessorImpl.java:43)
at java.base/java.lang.reflect.Method.invoke(Method.java:566)
at org.testng.internal.MethodInvocationHelper.invokeMethod(MethodInvocationHelper.java:124)
at org.testng.internal.Invoker.invokeMethod(Invoker.java:583)
at org.testng.internal.Invoker.retryFailed(Invoker.java:839)
at org.testng.internal.Invoker.invokeTestMethods(Invoker.java:1010)
at org.testng.internal.TestMethodWorker.invokeTestMethods(TestMethodWorker.java:125)
at org.testng.internal.TestMethodWorker.run(TestMethodWorker.java:109)
at org.testng.TestRunner.privateRun(TestRunner.java:648)
at org.testng.TestRunner.run(TestRunner.java:505)
at org.testng.SuiteRunner.runTest(SuiteRunner.java:455)
at org.testng.SuiteRunner.runSequentially(SuiteRunner.java:450)
at org.testng.SuiteRunner.privateRun(SuiteRunner.java:415)
at org.testng.SuiteRunner.run(SuiteRunner.java:364)
at org.testng.SuiteRunnerWorker.runSuite(SuiteRunnerWorker.java:52)
at org.testng.SuiteRunnerWorker.run(SuiteRunnerWorker.java:84)
at org.testng.TestNG.runSuitesSequentially(TestNG.java:1208)
at org.testng.TestNG.runSuitesLocally(TestNG.java:1137)
at org.testng.TestNG.runSuites(TestNG.java:1049)
at org.testng.TestNG.run(TestNG.java:1017)
at org.testng.remote.AbstractRemoteTestNG.run(AbstractRemoteTestNG.java:115)
at org.testng.remote.RemoteTestNG.initAndRun(RemoteTestNG.java:251)
at org.testng.remote.RemoteTestNG.main(RemoteTestNG.java:77)
]]>
    </error>
  </testcase> <!-- test1 -->
  <testcase classname="mytests.RetryAnalyzer" name="test3" time="0.003"/>
  <testcase classname="mytests.RetryAnalyzer" name="test2" time="0.008">
    <skipped/>
  </testcase> <!-- test2 -->
  <testcase classname="mytests.RetryAnalyzer" name="test1" time="0.009">
    <skipped/>
  </testcase> <!-- test1 -->
  <testcase classname="mytests.RetryAnalyzer" name="test1" time="0.023">
    <skipped/>
  </testcase> <!-- test1 -->
  <testcase classname="mytests.RetryAnalyzer" name="test1" time="0.009">
    <skipped/>
  </testcase> <!-- test1 -->
  <testcase classname="mytests.RetryAnalyzer" name="test2" time="0.003">
    <error message="expected:&lt;true&gt; but was:&lt;false&gt;" type="junit.framework.AssertionFailedError">
      <![CDATA[junit.framework.AssertionFailedError: expected:<true> but was:<false>
at junit.framework.Assert.fail(Assert.java:47)
at junit.framework.Assert.failNotEquals(Assert.java:282)
at junit.framework.Assert.assertEquals(Assert.java:64)
at junit.framework.Assert.assertEquals(Assert.java:149)
at junit.framework.Assert.assertEquals(Assert.java:155)
at mytests.RetryAnalyzer.test2(RetryAnalyzer.java:16)
at java.base/jdk.internal.reflect.NativeMethodAccessorImpl.invoke0(Native Method)
at java.base/jdk.internal.reflect.NativeMethodAccessorImpl.invoke(NativeMethodAccessorImpl.java:62)
at java.base/jdk.internal.reflect.DelegatingMethodAccessorImpl.invoke(DelegatingMethodAccessorImpl.java:43)
at java.base/java.lang.reflect.Method.invoke(Method.java:566)
at org.testng.internal.MethodInvocationHelper.invokeMethod(MethodInvocationHelper.java:124)
at org.testng.internal.Invoker.invokeMethod(Invoker.java:583)
at org.testng.internal.Invoker.retryFailed(Invoker.java:839)
at org.testng.internal.Invoker.invokeTestMethods(Invoker.java:1010)
at org.testng.internal.TestMethodWorker.invokeTestMethods(TestMethodWorker.java:125)
at org.testng.internal.TestMethodWorker.run(TestMethodWorker.java:109)
at org.testng.TestRunner.privateRun(TestRunner.java:648)
at org.testng.TestRunner.run(TestRunner.java:505)
at org.testng.SuiteRunner.runTest(SuiteRunner.java:455)
at org.testng.SuiteRunner.runSequentially(SuiteRunner.java:450)
at org.testng.SuiteRunner.privateRun(SuiteRunner.java:415)
at org.testng.SuiteRunner.run(SuiteRunner.java:364)
at org.testng.SuiteRunnerWorker.runSuite(SuiteRunnerWorker.java:52)
at org.testng.SuiteRunnerWorker.run(SuiteRunnerWorker.java:84)
at org.testng.TestNG.runSuitesSequentially(TestNG.java:1208)
at org.testng.TestNG.runSuitesLocally(TestNG.java:1137)
at org.testng.TestNG.runSuites(TestNG.java:1049)
at org.testng.TestNG.run(TestNG.java:1017)
at org.testng.remote.AbstractRemoteTestNG.run(AbstractRemoteTestNG.java:115)
at org.testng.remote.RemoteTestNG.initAndRun(RemoteTestNG.java:251)
at org.testng.remote.RemoteTestNG.main(RemoteTestNG.java:77)
]]>
    </error>
  </testcase> <!-- test2 -->
  <testcase classname="mytests.RetryAnalyzer" name="test2" time="0.003">
    <skipped/>
  </testcase> <!-- test2 -->
  <testcase classname="mytests.RetryAnalyzer" name="test2" time="0.003">
    <skipped/>
  </testcase> <!-- test2 -->
  <testcase classname="mytests.RetryAnalyzer" name="test1" time="0.003">
    <skipped/>
  </testcase> <!-- test1 -->
  <testcase classname="mytests.RetryAnalyzer" name="test2" time="0.012">
    <skipped/>
  </testcase> <!-- test2 -->
</testsuite> <!-- mytests.RetryAnalyzer -->
